<?xml version="1.0"?>
<robot xmlns:xacro="http://www.ros.org/wiki/xacro">
    <!-- Add a new link for the arm -->
    <link name="arm_link">
        <visual>
            <origin xyz="0 0 0" rpy="0 0 0" />
            <geometry>
                <box size="0.15 0.01 0.01" />
            </geometry>
            <material name="green" />
        </visual>
        <collision>
            <origin xyz="0 0 0" rpy="0 0 0" />
            <geometry>
                <box size="0.15 0.01 0.01" />
            </geometry>
        </collision>
        <inertial>
            <mass value="0.02" />
            <inertia ixx="0.001" ixy="0" ixz="0" iyy="0.001" iyz="0" izz="0.001" />
        </inertial>
    </link>

    <!-- Add a joint to attach the arm to the base or another link -->
    <joint name="arm_joint" type="revolute">
        <parent link="base_link" />
        <child link="arm_link" />
        <origin xyz="0 0 0.201" rpy="0 0 0" />
        <axis xyz="0 0 1" />
        <limit lower="-1.57" upper="1.57" effort="5" velocity="1.0" />
    </joint>
</robot>