<?xml version="1.0"?>
<robot xmlns:xacro="http://ros.org/wiki/xacro">

  <xacro:property name="roller_length" value="0.0185" />
  <xacro:property name="roller_radius" value="0.00475" />
  <xacro:property name="roller_mass" value="0.005" />

  <xacro:include filename="$(find armmy_omnibot)/urdf/roller/roller.transmission.xacro" />
  <xacro:include filename="$(find armmy_omnibot)/urdf/roller/roller.gazebo.xacro" />
  <xacro:include filename="$(find armmy_omnibot)/urdf/inertial_macros.xacro" />

  <xacro:macro name="roller_v0" params="prefix parent *joint_origin *joint_axis">
    <joint name="${prefix}_roller_joint" type="continuous">
      <xacro:insert_block name="joint_origin" />
      <parent link="${parent}" />
      <child link="${prefix}_roller_link" />
      <xacro:insert_block name="joint_axis" />
    </joint>

    <link name="${prefix}_roller_link">
      <visual>
        <geometry>
          <mesh filename="package://armmy_omnibot/meshes/omni_wheel/roller.stl"
            scale="0.001 0.001 0.001" />
        </geometry>
        <material name="black" />
      </visual>

      <collision>
        <geometry>
          <mesh filename="package://armmy_omnibot/meshes/omni_wheel/Roller_Simplyfier.stl"
            scale="0.001 0.001 0.001" />
        </geometry>
      </collision>

      <!-- <collision>
        <origin xyz="0 0 0.00925" rpy="0 0 0" />
        <geometry>
          <cylinder radius="${roller_radius}" length="${roller_length}" />
        </geometry>
      </collision> -->

      <xacro:inertial_cylinder mass="${roller_mass}" length="${roller_length}"
        radius="${roller_radius}">
        <origin xyz="0 0 0.00925" rpy="0 0 0" />
      </xacro:inertial_cylinder>

      <surface>
        <friction>
          <ode>
            <mu1>1.6</mu1>
            <mu2>1.6</mu2>
            <kp>1e15</kp>
            <kd>1e13</kd>
          </ode>
        </friction>
        <!-- <bounce>
          <restitution_coefficient>0.01</restitution_coefficient>
          <threshold>0</threshold>
        </bounce> -->
        <contact>
          <ode>
            <max_vel>10</max_vel>
          </ode>
          <max_contacts>2</max_contacts>
        </contact>
      </surface>
    </link>
  </xacro:macro>

</robot>