<sdf version='1.9'>
  <model name='omni_robot'>
    <link name='base_footprint'>
      <inertial>
        <pose>0 0 0 0 0 0</pose>
        <mass>0.050000000000000003</mass>
        <inertia>
          <ixx>2.026666666666666e-05</ixx>
          <ixy>0</ixy>
          <ixz>0</ixz>
          <iyy>2.026666666666666e-05</iyy>
          <iyz>0</iyz>
          <izz>4.0000000000000003e-05</izz>
        </inertia>
      </inertial>
      <collision name='base_footprint_fixed_joint_lump__base_link_collision'>
        <pose>0 0 0 0 0 0.7853981850000001</pose>
        <geometry>
          <mesh>
            <scale>0.001 0.001 0.001</scale>
            <uri>file:///home/armmy2530/Documents/ros2/ros2EIC/install/armmy_omnibot/share/armmy_omnibot/meshes/base_link.stl</uri>
          </mesh>
        </geometry>
        <surface>
          <contact>
            <ode/>
          </contact>
          <friction>
            <ode>
              <mu>0.050000000000000003</mu>
              <mu2>0.050000000000000003</mu2>
            </ode>
          </friction>
        </surface>
      </collision>
      <visual name='base_footprint_fixed_joint_lump__base_link_visual'>
        <pose>0 0 0 0 0 0.7853981850000001</pose>
        <geometry>
          <mesh>
            <scale>0.001 0.001 0.001</scale>
            <uri>file:///home/armmy2530/Documents/ros2/ros2EIC/install/armmy_omnibot/share/armmy_omnibot/meshes/base_link.stl</uri>
          </mesh>
        </geometry>
        <material>
          <diffuse>1 1 1 1</diffuse>
          <ambient>1 1 1 1</ambient>
        </material>
      </visual>
      <self_collide>false</self_collide>
      <sensor name='imu_sensor' type='imu'>
        <always_on>true</always_on>
        <update_rate>40</update_rate>
        <visualize>false</visualize>
        <topic>imu</topic>
        <pose>0 0 0.05 0 -0 0.785398</pose>
      </sensor>
      <sensor name='laser' type='gpu_lidar'>
        <visualize>false</visualize>
        <update_rate>40</update_rate>
        <lidar>
          <scan>
            <horizontal>
              <samples>360</samples>
              <resolution>1</resolution>
              <min_angle>-3.1400000000000001</min_angle>
              <max_angle>3.1400000000000001</max_angle>
            </horizontal>
          </scan>
          <range>
            <min>0.02</min>
            <max>10</max>
            <resolution>0.014999999999999999</resolution>
          </range>
          <noise>
            <type>gaussian</type>
            <mean>0</mean>
            <stddev>0.01</stddev>
          </noise>
        </lidar>
        <topic>scan</topic>
        <pose>0 0 0.05 0 -0 0.785398</pose>
        <gz_frame_id>top_lidar_link</gz_frame_id>
      </sensor>
    </link>
    <joint name='first_wheel_joint' type='revolute'>
      <pose relative_to='base_footprint'>-0.02713522331422381 0.0271352221418437 0 0 0 0.7853981850000001</pose>
      <parent>base_footprint</parent>
      <child>first_wheel_link</child>
      <axis>
        <xyz>0 1 0</xyz>
        <limit>
          <effort>100</effort>
          <velocity>100</velocity>
          <lower>-10000000000000000</lower>
          <upper>10000000000000000</upper>
        </limit>
        <dynamics>
          <spring_reference>0</spring_reference>
          <spring_stiffness>0</spring_stiffness>
        </dynamics>
      </axis>
    </joint>
    <link name='first_wheel_link'>
      <pose relative_to='first_wheel_joint'>0 0 0 0 0 0</pose>
      <inertial>
        <pose>0 0.00925 0 1.570796327 0 0</pose>
        <mass>0.050000000000000003</mass>
        <inertia>
          <ixx>5.254166666666667e-06</ixx>
          <ixy>0</ixy>
          <ixz>0</ixz>
          <iyy>5.254166666666667e-06</iyy>
          <iyz>0</iyz>
          <izz>7.6562500000000014e-06</izz>
        </inertia>
      </inertial>
      <visual name='first_wheel_link_visual'>
        <pose>0 0 0 0 0 0</pose>
        <geometry>
          <mesh>
            <scale>1 1 1</scale>
            <uri>model://armmy_omnibot/meshes/omni_wheel/wheel_assembly.dae</uri>
          </mesh>
        </geometry>
      </visual>
      <self_collide>false</self_collide>
    </link>
    <joint name='roller_first_1_joint' type='revolute'>
      <pose relative_to='first_wheel_link'>0.015 0.0046 0 0 0 1</pose>
      <parent>first_wheel_link</parent>
      <child>roller_first_1_link</child>
      <axis>
        <xyz>0 0 1</xyz>
        <limit>
          <lower>-10000000000000000</lower>
          <upper>10000000000000000</upper>
        </limit>
        <dynamics>
          <spring_reference>0</spring_reference>
          <spring_stiffness>0</spring_stiffness>
        </dynamics>
      </axis>
    </joint>
    <link name='roller_first_1_link'>
      <pose relative_to='roller_first_1_joint'>0 0 0 0 0 0</pose>
      <inertial>
        <pose>0 0.00925 0 1.570796327 0 0</pose>
        <mass>0.001</mass>
        <inertia>
          <ixx>1.6e-07</ixx>
          <ixy>0</ixy>
          <ixz>0</ixz>
          <iyy>1.6e-07</iyy>
          <iyz>0</iyz>
          <izz>1.6e-07</izz>
        </inertia>
      </inertial>
      <collision name='roller_first_1_link_collision'>
        <pose>0.015 0.0046 0 0 0 1</pose>
        <geometry>
          <sphere>
            <radius>0.02</radius>
          </sphere>
        </geometry>
      </collision>
      <visual name='roller_first_1_link_visual'>
        <pose>0.015 0.0046 0 0 0 1</pose>
        <geometry>
          <sphere>
            <radius>0.02</radius>
          </sphere>
        </geometry>
        <material>
          <diffuse>0 0 0 1</diffuse>
          <ambient>0 0 0 1</ambient>
        </material>
      </visual>
    </link>
    <joint name='roller_first_2_joint' type='revolute'>
      <pose relative_to='first_wheel_link'>0 0.0046 0.015 -1 0 0</pose>
      <parent>first_wheel_link</parent>
      <child>roller_first_2_link</child>
      <axis>
        <xyz>-1 0 0</xyz>
        <limit>
          <lower>-10000000000000000</lower>
          <upper>10000000000000000</upper>
        </limit>
        <dynamics>
          <spring_reference>0</spring_reference>
          <spring_stiffness>0</spring_stiffness>
        </dynamics>
      </axis>
    </joint>
    <link name='roller_first_2_link'>
      <pose relative_to='roller_first_2_joint'>0 0 0 0 0 0</pose>
      <inertial>
        <pose>0 0.00925 0 1.570796327 0 0</pose>
        <mass>0.001</mass>
        <inertia>
          <ixx>1.6e-07</ixx>
          <ixy>0</ixy>
          <ixz>0</ixz>
          <iyy>1.6e-07</iyy>
          <iyz>0</iyz>
          <izz>1.6e-07</izz>
        </inertia>
      </inertial>
      <collision name='roller_first_2_link_collision'>
        <pose>0 0.0046 0.015 -1 0 0</pose>
        <geometry>
          <sphere>
            <radius>0.02</radius>
          </sphere>
        </geometry>
      </collision>
      <visual name='roller_first_2_link_visual'>
        <pose>0 0.0046 0.015 -1 0 0</pose>
        <geometry>
          <sphere>
            <radius>0.02</radius>
          </sphere>
        </geometry>
        <material>
          <diffuse>0 0 0 1</diffuse>
          <ambient>0 0 0 1</ambient>
        </material>
      </visual>
    </link>
    <joint name='roller_first_3_joint' type='revolute'>
      <pose relative_to='first_wheel_link'>-0.015 0.0046 0 0 0 -1</pose>
      <parent>first_wheel_link</parent>
      <child>roller_first_3_link</child>
      <axis>
        <xyz>0 0 -1</xyz>
        <limit>
          <lower>-10000000000000000</lower>
          <upper>10000000000000000</upper>
        </limit>
        <dynamics>
          <spring_reference>0</spring_reference>
          <spring_stiffness>0</spring_stiffness>
        </dynamics>
      </axis>
    </joint>
    <link name='roller_first_3_link'>
      <pose relative_to='roller_first_3_joint'>0 0 0 0 0 0</pose>
      <inertial>
        <pose>0 0.00925 0 1.570796327 0 0</pose>
        <mass>0.001</mass>
        <inertia>
          <ixx>1.6e-07</ixx>
          <ixy>0</ixy>
          <ixz>0</ixz>
          <iyy>1.6e-07</iyy>
          <iyz>0</iyz>
          <izz>1.6e-07</izz>
        </inertia>
      </inertial>
      <collision name='roller_first_3_link_collision'>
        <pose>-0.015 0.0046 0 0 0 -1</pose>
        <geometry>
          <sphere>
            <radius>0.02</radius>
          </sphere>
        </geometry>
      </collision>
      <visual name='roller_first_3_link_visual'>
        <pose>-0.015 0.0046 0 0 0 -1</pose>
        <geometry>
          <sphere>
            <radius>0.02</radius>
          </sphere>
        </geometry>
        <material>
          <diffuse>0 0 0 1</diffuse>
          <ambient>0 0 0 1</ambient>
        </material>
      </visual>
    </link>
    <joint name='roller_first_4_joint' type='revolute'>
      <pose relative_to='first_wheel_link'>0 0.0046 -0.015 1 0 0</pose>
      <parent>first_wheel_link</parent>
      <child>roller_first_4_link</child>
      <axis>
        <xyz>1 0 0</xyz>
        <limit>
          <lower>-10000000000000000</lower>
          <upper>10000000000000000</upper>
        </limit>
        <dynamics>
          <spring_reference>0</spring_reference>
          <spring_stiffness>0</spring_stiffness>
        </dynamics>
      </axis>
    </joint>
    <link name='roller_first_4_link'>
      <pose relative_to='roller_first_4_joint'>0 0 0 0 0 0</pose>
      <inertial>
        <pose>0 0.00925 0 1.570796327 0 0</pose>
        <mass>0.001</mass>
        <inertia>
          <ixx>1.6e-07</ixx>
          <ixy>0</ixy>
          <ixz>0</ixz>
          <iyy>1.6e-07</iyy>
          <iyz>0</iyz>
          <izz>1.6e-07</izz>
        </inertia>
      </inertial>
      <collision name='roller_first_4_link_collision'>
        <pose>0 0.0046 -0.015 1 0 0</pose>
        <geometry>
          <sphere>
            <radius>0.02</radius>
          </sphere>
        </geometry>
      </collision>
      <visual name='roller_first_4_link_visual'>
        <pose>0 0.0046 -0.015 1 0 0</pose>
        <geometry>
          <sphere>
            <radius>0.02</radius>
          </sphere>
        </geometry>
        <material>
          <diffuse>0 0 0 1</diffuse>
          <ambient>0 0 0 1</ambient>
        </material>
      </visual>
    </link>
    <joint name='roller_first_5_joint' type='revolute'>
      <pose relative_to='first_wheel_link'>0.0106 0.0139 0.0106 -0.707107 0 0.707107</pose>
      <parent>first_wheel_link</parent>
      <child>roller_first_5_link</child>
      <axis>
        <xyz>-0.707107 0 0.707107</xyz>
        <limit>
          <lower>-10000000000000000</lower>
          <upper>10000000000000000</upper>
        </limit>
        <dynamics>
          <spring_reference>0</spring_reference>
          <spring_stiffness>0</spring_stiffness>
        </dynamics>
      </axis>
    </joint>
    <link name='roller_first_5_link'>
      <pose relative_to='roller_first_5_joint'>0 0 0 0 0 0</pose>
      <inertial>
        <pose>0 0.00925 0 1.570796327 0 0</pose>
        <mass>0.001</mass>
        <inertia>
          <ixx>1.6e-07</ixx>
          <ixy>0</ixy>
          <ixz>0</ixz>
          <iyy>1.6e-07</iyy>
          <iyz>0</iyz>
          <izz>1.6e-07</izz>
        </inertia>
      </inertial>
      <collision name='roller_first_5_link_collision'>
        <pose>0.0106 0.0139 0.0106 -0.707107 0 0.707107</pose>
        <geometry>
          <sphere>
            <radius>0.02</radius>
          </sphere>
        </geometry>
      </collision>
      <visual name='roller_first_5_link_visual'>
        <pose>0.0106 0.0139 0.0106 -0.707107 0 0.707107</pose>
        <geometry>
          <sphere>
            <radius>0.02</radius>
          </sphere>
        </geometry>
        <material>
          <diffuse>0 0 0 1</diffuse>
          <ambient>0 0 0 1</ambient>
        </material>
      </visual>
    </link>
    <joint name='roller_first_6_joint' type='revolute'>
      <pose relative_to='first_wheel_link'>-0.0106 0.0139 0.0106 -0.707107 0 -0.707107</pose>
      <parent>first_wheel_link</parent>
      <child>roller_first_6_link</child>
      <axis>
        <xyz>-0.707107 0 -0.707107</xyz>
        <limit>
          <lower>-10000000000000000</lower>
          <upper>10000000000000000</upper>
        </limit>
        <dynamics>
          <spring_reference>0</spring_reference>
          <spring_stiffness>0</spring_stiffness>
        </dynamics>
      </axis>
    </joint>
    <link name='roller_first_6_link'>
      <pose relative_to='roller_first_6_joint'>0 0 0 0 0 0</pose>
      <inertial>
        <pose>0 0.00925 0 1.570796327 0 0</pose>
        <mass>0.001</mass>
        <inertia>
          <ixx>1.6e-07</ixx>
          <ixy>0</ixy>
          <ixz>0</ixz>
          <iyy>1.6e-07</iyy>
          <iyz>0</iyz>
          <izz>1.6e-07</izz>
        </inertia>
      </inertial>
      <collision name='roller_first_6_link_collision'>
        <pose>-0.0106 0.0139 0.0106 -0.707107 0 -0.707107</pose>
        <geometry>
          <sphere>
            <radius>0.02</radius>
          </sphere>
        </geometry>
      </collision>
      <visual name='roller_first_6_link_visual'>
        <pose>-0.0106 0.0139 0.0106 -0.707107 0 -0.707107</pose>
        <geometry>
          <sphere>
            <radius>0.02</radius>
          </sphere>
        </geometry>
        <material>
          <diffuse>0 0 0 1</diffuse>
          <ambient>0 0 0 1</ambient>
        </material>
      </visual>
    </link>
    <joint name='roller_first_7_joint' type='revolute'>
      <pose relative_to='first_wheel_link'>-0.0106 0.0139 -0.0106 0.707107 0 -0.707107</pose>
      <parent>first_wheel_link</parent>
      <child>roller_first_7_link</child>
      <axis>
        <xyz>0.707107 0 -0.707107</xyz>
        <limit>
          <lower>-10000000000000000</lower>
          <upper>10000000000000000</upper>
        </limit>
        <dynamics>
          <spring_reference>0</spring_reference>
          <spring_stiffness>0</spring_stiffness>
        </dynamics>
      </axis>
    </joint>
    <link name='roller_first_7_link'>
      <pose relative_to='roller_first_7_joint'>0 0 0 0 0 0</pose>
      <inertial>
        <pose>0 0.00925 0 1.570796327 0 0</pose>
        <mass>0.001</mass>
        <inertia>
          <ixx>1.6e-07</ixx>
          <ixy>0</ixy>
          <ixz>0</ixz>
          <iyy>1.6e-07</iyy>
          <iyz>0</iyz>
          <izz>1.6e-07</izz>
        </inertia>
      </inertial>
      <collision name='roller_first_7_link_collision'>
        <pose>-0.0106 0.0139 -0.0106 0.707107 0 -0.707107</pose>
        <geometry>
          <sphere>
            <radius>0.02</radius>
          </sphere>
        </geometry>
      </collision>
      <visual name='roller_first_7_link_visual'>
        <pose>-0.0106 0.0139 -0.0106 0.707107 0 -0.707107</pose>
        <geometry>
          <sphere>
            <radius>0.02</radius>
          </sphere>
        </geometry>
        <material>
          <diffuse>0 0 0 1</diffuse>
          <ambient>0 0 0 1</ambient>
        </material>
      </visual>
    </link>
    <joint name='roller_first_8_joint' type='revolute'>
      <pose relative_to='first_wheel_link'>0.0106 0.0139 -0.0106 0.707107 0 0.707107</pose>
      <parent>first_wheel_link</parent>
      <child>roller_first_8_link</child>
      <axis>
        <xyz>0.707107 0 0.707107</xyz>
        <limit>
          <lower>-10000000000000000</lower>
          <upper>10000000000000000</upper>
        </limit>
        <dynamics>
          <spring_reference>0</spring_reference>
          <spring_stiffness>0</spring_stiffness>
        </dynamics>
      </axis>
    </joint>
    <link name='roller_first_8_link'>
      <pose relative_to='roller_first_8_joint'>0 0 0 0 0 0</pose>
      <inertial>
        <pose>0 0.00925 0 1.570796327 0 0</pose>
        <mass>0.001</mass>
        <inertia>
          <ixx>1.6e-07</ixx>
          <ixy>0</ixy>
          <ixz>0</ixz>
          <iyy>1.6e-07</iyy>
          <iyz>0</iyz>
          <izz>1.6e-07</izz>
        </inertia>
      </inertial>
      <collision name='roller_first_8_link_collision'>
        <pose>0.0106 0.0139 -0.0106 0.707107 0 0.707107</pose>
        <geometry>
          <sphere>
            <radius>0.02</radius>
          </sphere>
        </geometry>
      </collision>
      <visual name='roller_first_8_link_visual'>
        <pose>0.0106 0.0139 -0.0106 0.707107 0 0.707107</pose>
        <geometry>
          <sphere>
            <radius>0.02</radius>
          </sphere>
        </geometry>
        <material>
          <diffuse>0 0 0 1</diffuse>
          <ambient>0 0 0 1</ambient>
        </material>
      </visual>
    </link>
    <joint name='fourth_wheel_joint' type='revolute'>
      <pose relative_to='base_footprint'>0.0271352221418437 0.02713522331422381 0 0 0 -0.7853980121795862</pose>
      <parent>base_footprint</parent>
      <child>fourth_wheel_link</child>
      <axis>
        <xyz>0 1 0</xyz>
        <limit>
          <effort>100</effort>
          <velocity>100</velocity>
          <lower>-10000000000000000</lower>
          <upper>10000000000000000</upper>
        </limit>
        <dynamics>
          <spring_reference>0</spring_reference>
          <spring_stiffness>0</spring_stiffness>
        </dynamics>
      </axis>
    </joint>
    <link name='fourth_wheel_link'>
      <pose relative_to='fourth_wheel_joint'>0 0 0 0 0 0</pose>
      <inertial>
        <pose>0 0.00925 0 1.570796327 0 0</pose>
        <mass>0.050000000000000003</mass>
        <inertia>
          <ixx>5.254166666666667e-06</ixx>
          <ixy>0</ixy>
          <ixz>0</ixz>
          <iyy>5.254166666666667e-06</iyy>
          <iyz>0</iyz>
          <izz>7.6562500000000014e-06</izz>
        </inertia>
      </inertial>
      <visual name='fourth_wheel_link_visual'>
        <pose>0 0 0 0 0 0</pose>
        <geometry>
          <mesh>
            <scale>1 1 1</scale>
            <uri>model://armmy_omnibot/meshes/omni_wheel/wheel_assembly.dae</uri>
          </mesh>
        </geometry>
      </visual>
      <self_collide>false</self_collide>
    </link>
    <joint name='roller_fourth_1_joint' type='revolute'>
      <pose relative_to='fourth_wheel_link'>0.015 0.0046 0 0 0 1</pose>
      <parent>fourth_wheel_link</parent>
      <child>roller_fourth_1_link</child>
      <axis>
        <xyz>0 0 1</xyz>
        <limit>
          <lower>-10000000000000000</lower>
          <upper>10000000000000000</upper>
        </limit>
        <dynamics>
          <spring_reference>0</spring_reference>
          <spring_stiffness>0</spring_stiffness>
        </dynamics>
      </axis>
    </joint>
    <link name='roller_fourth_1_link'>
      <pose relative_to='roller_fourth_1_joint'>0 0 0 0 0 0</pose>
      <inertial>
        <pose>0 0.00925 0 1.570796327 0 0</pose>
        <mass>0.001</mass>
        <inertia>
          <ixx>1.6e-07</ixx>
          <ixy>0</ixy>
          <ixz>0</ixz>
          <iyy>1.6e-07</iyy>
          <iyz>0</iyz>
          <izz>1.6e-07</izz>
        </inertia>
      </inertial>
      <collision name='roller_fourth_1_link_collision'>
        <pose>0.015 0.0046 0 0 0 1</pose>
        <geometry>
          <sphere>
            <radius>0.02</radius>
          </sphere>
        </geometry>
      </collision>
      <visual name='roller_fourth_1_link_visual'>
        <pose>0.015 0.0046 0 0 0 1</pose>
        <geometry>
          <sphere>
            <radius>0.02</radius>
          </sphere>
        </geometry>
        <material>
          <diffuse>0 0 0 1</diffuse>
          <ambient>0 0 0 1</ambient>
        </material>
      </visual>
    </link>
    <joint name='roller_fourth_2_joint' type='revolute'>
      <pose relative_to='fourth_wheel_link'>0 0.0046 0.015 -1 0 0</pose>
      <parent>fourth_wheel_link</parent>
      <child>roller_fourth_2_link</child>
      <axis>
        <xyz>-1 0 0</xyz>
        <limit>
          <lower>-10000000000000000</lower>
          <upper>10000000000000000</upper>
        </limit>
        <dynamics>
          <spring_reference>0</spring_reference>
          <spring_stiffness>0</spring_stiffness>
        </dynamics>
      </axis>
    </joint>
    <link name='roller_fourth_2_link'>
      <pose relative_to='roller_fourth_2_joint'>0 0 0 0 0 0</pose>
      <inertial>
        <pose>0 0.00925 0 1.570796327 0 0</pose>
        <mass>0.001</mass>
        <inertia>
          <ixx>1.6e-07</ixx>
          <ixy>0</ixy>
          <ixz>0</ixz>
          <iyy>1.6e-07</iyy>
          <iyz>0</iyz>
          <izz>1.6e-07</izz>
        </inertia>
      </inertial>
      <collision name='roller_fourth_2_link_collision'>
        <pose>0 0.0046 0.015 -1 0 0</pose>
        <geometry>
          <sphere>
            <radius>0.02</radius>
          </sphere>
        </geometry>
      </collision>
      <visual name='roller_fourth_2_link_visual'>
        <pose>0 0.0046 0.015 -1 0 0</pose>
        <geometry>
          <sphere>
            <radius>0.02</radius>
          </sphere>
        </geometry>
        <material>
          <diffuse>0 0 0 1</diffuse>
          <ambient>0 0 0 1</ambient>
        </material>
      </visual>
    </link>
    <joint name='roller_fourth_3_joint' type='revolute'>
      <pose relative_to='fourth_wheel_link'>-0.015 0.0046 0 0 0 -1</pose>
      <parent>fourth_wheel_link</parent>
      <child>roller_fourth_3_link</child>
      <axis>
        <xyz>0 0 -1</xyz>
        <limit>
          <lower>-10000000000000000</lower>
          <upper>10000000000000000</upper>
        </limit>
        <dynamics>
          <spring_reference>0</spring_reference>
          <spring_stiffness>0</spring_stiffness>
        </dynamics>
      </axis>
    </joint>
    <link name='roller_fourth_3_link'>
      <pose relative_to='roller_fourth_3_joint'>0 0 0 0 0 0</pose>
      <inertial>
        <pose>0 0.00925 0 1.570796327 0 0</pose>
        <mass>0.001</mass>
        <inertia>
          <ixx>1.6e-07</ixx>
          <ixy>0</ixy>
          <ixz>0</ixz>
          <iyy>1.6e-07</iyy>
          <iyz>0</iyz>
          <izz>1.6e-07</izz>
        </inertia>
      </inertial>
      <collision name='roller_fourth_3_link_collision'>
        <pose>-0.015 0.0046 0 0 0 -1</pose>
        <geometry>
          <sphere>
            <radius>0.02</radius>
          </sphere>
        </geometry>
      </collision>
      <visual name='roller_fourth_3_link_visual'>
        <pose>-0.015 0.0046 0 0 0 -1</pose>
        <geometry>
          <sphere>
            <radius>0.02</radius>
          </sphere>
        </geometry>
        <material>
          <diffuse>0 0 0 1</diffuse>
          <ambient>0 0 0 1</ambient>
        </material>
      </visual>
    </link>
    <joint name='roller_fourth_4_joint' type='revolute'>
      <pose relative_to='fourth_wheel_link'>0 0.0046 -0.015 1 0 0</pose>
      <parent>fourth_wheel_link</parent>
      <child>roller_fourth_4_link</child>
      <axis>
        <xyz>1 0 0</xyz>
        <limit>
          <lower>-10000000000000000</lower>
          <upper>10000000000000000</upper>
        </limit>
        <dynamics>
          <spring_reference>0</spring_reference>
          <spring_stiffness>0</spring_stiffness>
        </dynamics>
      </axis>
    </joint>
    <link name='roller_fourth_4_link'>
      <pose relative_to='roller_fourth_4_joint'>0 0 0 0 0 0</pose>
      <inertial>
        <pose>0 0.00925 0 1.570796327 0 0</pose>
        <mass>0.001</mass>
        <inertia>
          <ixx>1.6e-07</ixx>
          <ixy>0</ixy>
          <ixz>0</ixz>
          <iyy>1.6e-07</iyy>
          <iyz>0</iyz>
          <izz>1.6e-07</izz>
        </inertia>
      </inertial>
      <collision name='roller_fourth_4_link_collision'>
        <pose>0 0.0046 -0.015 1 0 0</pose>
        <geometry>
          <sphere>
            <radius>0.02</radius>
          </sphere>
        </geometry>
      </collision>
      <visual name='roller_fourth_4_link_visual'>
        <pose>0 0.0046 -0.015 1 0 0</pose>
        <geometry>
          <sphere>
            <radius>0.02</radius>
          </sphere>
        </geometry>
        <material>
          <diffuse>0 0 0 1</diffuse>
          <ambient>0 0 0 1</ambient>
        </material>
      </visual>
    </link>
    <joint name='roller_fourth_5_joint' type='revolute'>
      <pose relative_to='fourth_wheel_link'>0.0106 0.0139 0.0106 -0.707107 0 0.707107</pose>
      <parent>fourth_wheel_link</parent>
      <child>roller_fourth_5_link</child>
      <axis>
        <xyz>-0.707107 0 0.707107</xyz>
        <limit>
          <lower>-10000000000000000</lower>
          <upper>10000000000000000</upper>
        </limit>
        <dynamics>
          <spring_reference>0</spring_reference>
          <spring_stiffness>0</spring_stiffness>
        </dynamics>
      </axis>
    </joint>
    <link name='roller_fourth_5_link'>
      <pose relative_to='roller_fourth_5_joint'>0 0 0 0 0 0</pose>
      <inertial>
        <pose>0 0.00925 0 1.570796327 0 0</pose>
        <mass>0.001</mass>
        <inertia>
          <ixx>1.6e-07</ixx>
          <ixy>0</ixy>
          <ixz>0</ixz>
          <iyy>1.6e-07</iyy>
          <iyz>0</iyz>
          <izz>1.6e-07</izz>
        </inertia>
      </inertial>
      <collision name='roller_fourth_5_link_collision'>
        <pose>0.0106 0.0139 0.0106 -0.707107 0 0.707107</pose>
        <geometry>
          <sphere>
            <radius>0.02</radius>
          </sphere>
        </geometry>
      </collision>
      <visual name='roller_fourth_5_link_visual'>
        <pose>0.0106 0.0139 0.0106 -0.707107 0 0.707107</pose>
        <geometry>
          <sphere>
            <radius>0.02</radius>
          </sphere>
        </geometry>
        <material>
          <diffuse>0 0 0 1</diffuse>
          <ambient>0 0 0 1</ambient>
        </material>
      </visual>
    </link>
    <joint name='roller_fourth_6_joint' type='revolute'>
      <pose relative_to='fourth_wheel_link'>-0.0106 0.0139 0.0106 -0.707107 0 -0.707107</pose>
      <parent>fourth_wheel_link</parent>
      <child>roller_fourth_6_link</child>
      <axis>
        <xyz>-0.707107 0 -0.707107</xyz>
        <limit>
          <lower>-10000000000000000</lower>
          <upper>10000000000000000</upper>
        </limit>
        <dynamics>
          <spring_reference>0</spring_reference>
          <spring_stiffness>0</spring_stiffness>
        </dynamics>
      </axis>
    </joint>
    <link name='roller_fourth_6_link'>
      <pose relative_to='roller_fourth_6_joint'>0 0 0 0 0 0</pose>
      <inertial>
        <pose>0 0.00925 0 1.570796327 0 0</pose>
        <mass>0.001</mass>
        <inertia>
          <ixx>1.6e-07</ixx>
          <ixy>0</ixy>
          <ixz>0</ixz>
          <iyy>1.6e-07</iyy>
          <iyz>0</iyz>
          <izz>1.6e-07</izz>
        </inertia>
      </inertial>
      <collision name='roller_fourth_6_link_collision'>
        <pose>-0.0106 0.0139 0.0106 -0.707107 0 -0.707107</pose>
        <geometry>
          <sphere>
            <radius>0.02</radius>
          </sphere>
        </geometry>
      </collision>
      <visual name='roller_fourth_6_link_visual'>
        <pose>-0.0106 0.0139 0.0106 -0.707107 0 -0.707107</pose>
        <geometry>
          <sphere>
            <radius>0.02</radius>
          </sphere>
        </geometry>
        <material>
          <diffuse>0 0 0 1</diffuse>
          <ambient>0 0 0 1</ambient>
        </material>
      </visual>
    </link>
    <joint name='roller_fourth_7_joint' type='revolute'>
      <pose relative_to='fourth_wheel_link'>-0.0106 0.0139 -0.0106 0.707107 0 -0.707107</pose>
      <parent>fourth_wheel_link</parent>
      <child>roller_fourth_7_link</child>
      <axis>
        <xyz>0.707107 0 -0.707107</xyz>
        <limit>
          <lower>-10000000000000000</lower>
          <upper>10000000000000000</upper>
        </limit>
        <dynamics>
          <spring_reference>0</spring_reference>
          <spring_stiffness>0</spring_stiffness>
        </dynamics>
      </axis>
    </joint>
    <link name='roller_fourth_7_link'>
      <pose relative_to='roller_fourth_7_joint'>0 0 0 0 0 0</pose>
      <inertial>
        <pose>0 0.00925 0 1.570796327 0 0</pose>
        <mass>0.001</mass>
        <inertia>
          <ixx>1.6e-07</ixx>
          <ixy>0</ixy>
          <ixz>0</ixz>
          <iyy>1.6e-07</iyy>
          <iyz>0</iyz>
          <izz>1.6e-07</izz>
        </inertia>
      </inertial>
      <collision name='roller_fourth_7_link_collision'>
        <pose>-0.0106 0.0139 -0.0106 0.707107 0 -0.707107</pose>
        <geometry>
          <sphere>
            <radius>0.02</radius>
          </sphere>
        </geometry>
      </collision>
      <visual name='roller_fourth_7_link_visual'>
        <pose>-0.0106 0.0139 -0.0106 0.707107 0 -0.707107</pose>
        <geometry>
          <sphere>
            <radius>0.02</radius>
          </sphere>
        </geometry>
        <material>
          <diffuse>0 0 0 1</diffuse>
          <ambient>0 0 0 1</ambient>
        </material>
      </visual>
    </link>
    <joint name='roller_fourth_8_joint' type='revolute'>
      <pose relative_to='fourth_wheel_link'>0.0106 0.0139 -0.0106 0.707107 0 0.707107</pose>
      <parent>fourth_wheel_link</parent>
      <child>roller_fourth_8_link</child>
      <axis>
        <xyz>0.707107 0 0.707107</xyz>
        <limit>
          <lower>-10000000000000000</lower>
          <upper>10000000000000000</upper>
        </limit>
        <dynamics>
          <spring_reference>0</spring_reference>
          <spring_stiffness>0</spring_stiffness>
        </dynamics>
      </axis>
    </joint>
    <link name='roller_fourth_8_link'>
      <pose relative_to='roller_fourth_8_joint'>0 0 0 0 0 0</pose>
      <inertial>
        <pose>0 0.00925 0 1.570796327 0 0</pose>
        <mass>0.001</mass>
        <inertia>
          <ixx>1.6e-07</ixx>
          <ixy>0</ixy>
          <ixz>0</ixz>
          <iyy>1.6e-07</iyy>
          <iyz>0</iyz>
          <izz>1.6e-07</izz>
        </inertia>
      </inertial>
      <collision name='roller_fourth_8_link_collision'>
        <pose>0.0106 0.0139 -0.0106 0.707107 0 0.707107</pose>
        <geometry>
          <sphere>
            <radius>0.02</radius>
          </sphere>
        </geometry>
      </collision>
      <visual name='roller_fourth_8_link_visual'>
        <pose>0.0106 0.0139 -0.0106 0.707107 0 0.707107</pose>
        <geometry>
          <sphere>
            <radius>0.02</radius>
          </sphere>
        </geometry>
        <material>
          <diffuse>0 0 0 1</diffuse>
          <ambient>0 0 0 1</ambient>
        </material>
      </visual>
    </link>
    <joint name='second_wheel_joint' type='revolute'>
      <pose relative_to='base_footprint'>-0.0271352221418437 -0.02713522331422381 0 0 0 2.356194555</pose>
      <parent>base_footprint</parent>
      <child>second_wheel_link</child>
      <axis>
        <xyz>0 1 0</xyz>
        <limit>
          <effort>100</effort>
          <velocity>100</velocity>
          <lower>-10000000000000000</lower>
          <upper>10000000000000000</upper>
        </limit>
        <dynamics>
          <spring_reference>0</spring_reference>
          <spring_stiffness>0</spring_stiffness>
        </dynamics>
      </axis>
    </joint>
    <link name='second_wheel_link'>
      <pose relative_to='second_wheel_joint'>0 0 0 0 0 0</pose>
      <inertial>
        <pose>0 0.00925 0 1.570796327 0 0</pose>
        <mass>0.050000000000000003</mass>
        <inertia>
          <ixx>5.254166666666667e-06</ixx>
          <ixy>0</ixy>
          <ixz>0</ixz>
          <iyy>5.254166666666667e-06</iyy>
          <iyz>0</iyz>
          <izz>7.6562500000000014e-06</izz>
        </inertia>
      </inertial>
      <visual name='second_wheel_link_visual'>
        <pose>0 0 0 0 0 0</pose>
        <geometry>
          <mesh>
            <scale>1 1 1</scale>
            <uri>model://armmy_omnibot/meshes/omni_wheel/wheel_assembly.dae</uri>
          </mesh>
        </geometry>
      </visual>
      <self_collide>false</self_collide>
    </link>
    <joint name='roller_second_1_joint' type='revolute'>
      <pose relative_to='second_wheel_link'>0.015 0.0046 0 0 0 1</pose>
      <parent>second_wheel_link</parent>
      <child>roller_second_1_link</child>
      <axis>
        <xyz>0 0 1</xyz>
        <limit>
          <lower>-10000000000000000</lower>
          <upper>10000000000000000</upper>
        </limit>
        <dynamics>
          <spring_reference>0</spring_reference>
          <spring_stiffness>0</spring_stiffness>
        </dynamics>
      </axis>
    </joint>
    <link name='roller_second_1_link'>
      <pose relative_to='roller_second_1_joint'>0 0 0 0 0 0</pose>
      <inertial>
        <pose>0 0.00925 0 1.570796327 0 0</pose>
        <mass>0.001</mass>
        <inertia>
          <ixx>1.6e-07</ixx>
          <ixy>0</ixy>
          <ixz>0</ixz>
          <iyy>1.6e-07</iyy>
          <iyz>0</iyz>
          <izz>1.6e-07</izz>
        </inertia>
      </inertial>
      <collision name='roller_second_1_link_collision'>
        <pose>0.015 0.0046 0 0 0 1</pose>
        <geometry>
          <sphere>
            <radius>0.02</radius>
          </sphere>
        </geometry>
      </collision>
      <visual name='roller_second_1_link_visual'>
        <pose>0.015 0.0046 0 0 0 1</pose>
        <geometry>
          <sphere>
            <radius>0.02</radius>
          </sphere>
        </geometry>
        <material>
          <diffuse>0 0 0 1</diffuse>
          <ambient>0 0 0 1</ambient>
        </material>
      </visual>
    </link>
    <joint name='roller_second_2_joint' type='revolute'>
      <pose relative_to='second_wheel_link'>0 0.0046 0.015 -1 0 0</pose>
      <parent>second_wheel_link</parent>
      <child>roller_second_2_link</child>
      <axis>
        <xyz>-1 0 0</xyz>
        <limit>
          <lower>-10000000000000000</lower>
          <upper>10000000000000000</upper>
        </limit>
        <dynamics>
          <spring_reference>0</spring_reference>
          <spring_stiffness>0</spring_stiffness>
        </dynamics>
      </axis>
    </joint>
    <link name='roller_second_2_link'>
      <pose relative_to='roller_second_2_joint'>0 0 0 0 0 0</pose>
      <inertial>
        <pose>0 0.00925 0 1.570796327 0 0</pose>
        <mass>0.001</mass>
        <inertia>
          <ixx>1.6e-07</ixx>
          <ixy>0</ixy>
          <ixz>0</ixz>
          <iyy>1.6e-07</iyy>
          <iyz>0</iyz>
          <izz>1.6e-07</izz>
        </inertia>
      </inertial>
      <collision name='roller_second_2_link_collision'>
        <pose>0 0.0046 0.015 -1 0 0</pose>
        <geometry>
          <sphere>
            <radius>0.02</radius>
          </sphere>
        </geometry>
      </collision>
      <visual name='roller_second_2_link_visual'>
        <pose>0 0.0046 0.015 -1 0 0</pose>
        <geometry>
          <sphere>
            <radius>0.02</radius>
          </sphere>
        </geometry>
        <material>
          <diffuse>0 0 0 1</diffuse>
          <ambient>0 0 0 1</ambient>
        </material>
      </visual>
    </link>
    <joint name='roller_second_3_joint' type='revolute'>
      <pose relative_to='second_wheel_link'>-0.015 0.0046 0 0 0 -1</pose>
      <parent>second_wheel_link</parent>
      <child>roller_second_3_link</child>
      <axis>
        <xyz>0 0 -1</xyz>
        <limit>
          <lower>-10000000000000000</lower>
          <upper>10000000000000000</upper>
        </limit>
        <dynamics>
          <spring_reference>0</spring_reference>
          <spring_stiffness>0</spring_stiffness>
        </dynamics>
      </axis>
    </joint>
    <link name='roller_second_3_link'>
      <pose relative_to='roller_second_3_joint'>0 0 0 0 0 0</pose>
      <inertial>
        <pose>0 0.00925 0 1.570796327 0 0</pose>
        <mass>0.001</mass>
        <inertia>
          <ixx>1.6e-07</ixx>
          <ixy>0</ixy>
          <ixz>0</ixz>
          <iyy>1.6e-07</iyy>
          <iyz>0</iyz>
          <izz>1.6e-07</izz>
        </inertia>
      </inertial>
      <collision name='roller_second_3_link_collision'>
        <pose>-0.015 0.0046 0 0 0 -1</pose>
        <geometry>
          <sphere>
            <radius>0.02</radius>
          </sphere>
        </geometry>
      </collision>
      <visual name='roller_second_3_link_visual'>
        <pose>-0.015 0.0046 0 0 0 -1</pose>
        <geometry>
          <sphere>
            <radius>0.02</radius>
          </sphere>
        </geometry>
        <material>
          <diffuse>0 0 0 1</diffuse>
          <ambient>0 0 0 1</ambient>
        </material>
      </visual>
    </link>
    <joint name='roller_second_4_joint' type='revolute'>
      <pose relative_to='second_wheel_link'>0 0.0046 -0.015 1 0 0</pose>
      <parent>second_wheel_link</parent>
      <child>roller_second_4_link</child>
      <axis>
        <xyz>1 0 0</xyz>
        <limit>
          <lower>-10000000000000000</lower>
          <upper>10000000000000000</upper>
        </limit>
        <dynamics>
          <spring_reference>0</spring_reference>
          <spring_stiffness>0</spring_stiffness>
        </dynamics>
      </axis>
    </joint>
    <link name='roller_second_4_link'>
      <pose relative_to='roller_second_4_joint'>0 0 0 0 0 0</pose>
      <inertial>
        <pose>0 0.00925 0 1.570796327 0 0</pose>
        <mass>0.001</mass>
        <inertia>
          <ixx>1.6e-07</ixx>
          <ixy>0</ixy>
          <ixz>0</ixz>
          <iyy>1.6e-07</iyy>
          <iyz>0</iyz>
          <izz>1.6e-07</izz>
        </inertia>
      </inertial>
      <collision name='roller_second_4_link_collision'>
        <pose>0 0.0046 -0.015 1 0 0</pose>
        <geometry>
          <sphere>
            <radius>0.02</radius>
          </sphere>
        </geometry>
      </collision>
      <visual name='roller_second_4_link_visual'>
        <pose>0 0.0046 -0.015 1 0 0</pose>
        <geometry>
          <sphere>
            <radius>0.02</radius>
          </sphere>
        </geometry>
        <material>
          <diffuse>0 0 0 1</diffuse>
          <ambient>0 0 0 1</ambient>
        </material>
      </visual>
    </link>
    <joint name='roller_second_5_joint' type='revolute'>
      <pose relative_to='second_wheel_link'>0.0106 0.0139 0.0106 -0.707107 0 0.707107</pose>
      <parent>second_wheel_link</parent>
      <child>roller_second_5_link</child>
      <axis>
        <xyz>-0.707107 0 0.707107</xyz>
        <limit>
          <lower>-10000000000000000</lower>
          <upper>10000000000000000</upper>
        </limit>
        <dynamics>
          <spring_reference>0</spring_reference>
          <spring_stiffness>0</spring_stiffness>
        </dynamics>
      </axis>
    </joint>
    <link name='roller_second_5_link'>
      <pose relative_to='roller_second_5_joint'>0 0 0 0 0 0</pose>
      <inertial>
        <pose>0 0.00925 0 1.570796327 0 0</pose>
        <mass>0.001</mass>
        <inertia>
          <ixx>1.6e-07</ixx>
          <ixy>0</ixy>
          <ixz>0</ixz>
          <iyy>1.6e-07</iyy>
          <iyz>0</iyz>
          <izz>1.6e-07</izz>
        </inertia>
      </inertial>
      <collision name='roller_second_5_link_collision'>
        <pose>0.0106 0.0139 0.0106 -0.707107 0 0.707107</pose>
        <geometry>
          <sphere>
            <radius>0.02</radius>
          </sphere>
        </geometry>
      </collision>
      <visual name='roller_second_5_link_visual'>
        <pose>0.0106 0.0139 0.0106 -0.707107 0 0.707107</pose>
        <geometry>
          <sphere>
            <radius>0.02</radius>
          </sphere>
        </geometry>
        <material>
          <diffuse>0 0 0 1</diffuse>
          <ambient>0 0 0 1</ambient>
        </material>
      </visual>
    </link>
    <joint name='roller_second_6_joint' type='revolute'>
      <pose relative_to='second_wheel_link'>-0.0106 0.0139 0.0106 -0.707107 0 -0.707107</pose>
      <parent>second_wheel_link</parent>
      <child>roller_second_6_link</child>
      <axis>
        <xyz>-0.707107 0 -0.707107</xyz>
        <limit>
          <lower>-10000000000000000</lower>
          <upper>10000000000000000</upper>
        </limit>
        <dynamics>
          <spring_reference>0</spring_reference>
          <spring_stiffness>0</spring_stiffness>
        </dynamics>
      </axis>
    </joint>
    <link name='roller_second_6_link'>
      <pose relative_to='roller_second_6_joint'>0 0 0 0 0 0</pose>
      <inertial>
        <pose>0 0.00925 0 1.570796327 0 0</pose>
        <mass>0.001</mass>
        <inertia>
          <ixx>1.6e-07</ixx>
          <ixy>0</ixy>
          <ixz>0</ixz>
          <iyy>1.6e-07</iyy>
          <iyz>0</iyz>
          <izz>1.6e-07</izz>
        </inertia>
      </inertial>
      <collision name='roller_second_6_link_collision'>
        <pose>-0.0106 0.0139 0.0106 -0.707107 0 -0.707107</pose>
        <geometry>
          <sphere>
            <radius>0.02</radius>
          </sphere>
        </geometry>
      </collision>
      <visual name='roller_second_6_link_visual'>
        <pose>-0.0106 0.0139 0.0106 -0.707107 0 -0.707107</pose>
        <geometry>
          <sphere>
            <radius>0.02</radius>
          </sphere>
        </geometry>
        <material>
          <diffuse>0 0 0 1</diffuse>
          <ambient>0 0 0 1</ambient>
        </material>
      </visual>
    </link>
    <joint name='roller_second_7_joint' type='revolute'>
      <pose relative_to='second_wheel_link'>-0.0106 0.0139 -0.0106 0.707107 0 -0.707107</pose>
      <parent>second_wheel_link</parent>
      <child>roller_second_7_link</child>
      <axis>
        <xyz>0.707107 0 -0.707107</xyz>
        <limit>
          <lower>-10000000000000000</lower>
          <upper>10000000000000000</upper>
        </limit>
        <dynamics>
          <spring_reference>0</spring_reference>
          <spring_stiffness>0</spring_stiffness>
        </dynamics>
      </axis>
    </joint>
    <link name='roller_second_7_link'>
      <pose relative_to='roller_second_7_joint'>0 0 0 0 0 0</pose>
      <inertial>
        <pose>0 0.00925 0 1.570796327 0 0</pose>
        <mass>0.001</mass>
        <inertia>
          <ixx>1.6e-07</ixx>
          <ixy>0</ixy>
          <ixz>0</ixz>
          <iyy>1.6e-07</iyy>
          <iyz>0</iyz>
          <izz>1.6e-07</izz>
        </inertia>
      </inertial>
      <collision name='roller_second_7_link_collision'>
        <pose>-0.0106 0.0139 -0.0106 0.707107 0 -0.707107</pose>
        <geometry>
          <sphere>
            <radius>0.02</radius>
          </sphere>
        </geometry>
      </collision>
      <visual name='roller_second_7_link_visual'>
        <pose>-0.0106 0.0139 -0.0106 0.707107 0 -0.707107</pose>
        <geometry>
          <sphere>
            <radius>0.02</radius>
          </sphere>
        </geometry>
        <material>
          <diffuse>0 0 0 1</diffuse>
          <ambient>0 0 0 1</ambient>
        </material>
      </visual>
    </link>
    <joint name='roller_second_8_joint' type='revolute'>
      <pose relative_to='second_wheel_link'>0.0106 0.0139 -0.0106 0.707107 0 0.707107</pose>
      <parent>second_wheel_link</parent>
      <child>roller_second_8_link</child>
      <axis>
        <xyz>0.707107 0 0.707107</xyz>
        <limit>
          <lower>-10000000000000000</lower>
          <upper>10000000000000000</upper>
        </limit>
        <dynamics>
          <spring_reference>0</spring_reference>
          <spring_stiffness>0</spring_stiffness>
        </dynamics>
      </axis>
    </joint>
    <link name='roller_second_8_link'>
      <pose relative_to='roller_second_8_joint'>0 0 0 0 0 0</pose>
      <inertial>
        <pose>0 0.00925 0 1.570796327 0 0</pose>
        <mass>0.001</mass>
        <inertia>
          <ixx>1.6e-07</ixx>
          <ixy>0</ixy>
          <ixz>0</ixz>
          <iyy>1.6e-07</iyy>
          <iyz>0</iyz>
          <izz>1.6e-07</izz>
        </inertia>
      </inertial>
      <collision name='roller_second_8_link_collision'>
        <pose>0.0106 0.0139 -0.0106 0.707107 0 0.707107</pose>
        <geometry>
          <sphere>
            <radius>0.02</radius>
          </sphere>
        </geometry>
      </collision>
      <visual name='roller_second_8_link_visual'>
        <pose>0.0106 0.0139 -0.0106 0.707107 0 0.707107</pose>
        <geometry>
          <sphere>
            <radius>0.02</radius>
          </sphere>
        </geometry>
        <material>
          <diffuse>0 0 0 1</diffuse>
          <ambient>0 0 0 1</ambient>
        </material>
      </visual>
    </link>
    <joint name='third_wheel_joint' type='revolute'>
      <pose relative_to='base_footprint'>0.02713522331422381 -0.0271352221418437 0 0 0 -2.356194382179586</pose>
      <parent>base_footprint</parent>
      <child>third_wheel_link</child>
      <axis>
        <xyz>0 1 0</xyz>
        <limit>
          <effort>100</effort>
          <velocity>100</velocity>
          <lower>-10000000000000000</lower>
          <upper>10000000000000000</upper>
        </limit>
        <dynamics>
          <spring_reference>0</spring_reference>
          <spring_stiffness>0</spring_stiffness>
        </dynamics>
      </axis>
    </joint>
    <link name='third_wheel_link'>
      <pose relative_to='third_wheel_joint'>0 0 0 0 0 0</pose>
      <inertial>
        <pose>0 0.00925 0 1.570796327 0 0</pose>
        <mass>0.050000000000000003</mass>
        <inertia>
          <ixx>5.254166666666667e-06</ixx>
          <ixy>0</ixy>
          <ixz>0</ixz>
          <iyy>5.254166666666667e-06</iyy>
          <iyz>0</iyz>
          <izz>7.6562500000000014e-06</izz>
        </inertia>
      </inertial>
      <visual name='third_wheel_link_visual'>
        <pose>0 0 0 0 0 0</pose>
        <geometry>
          <mesh>
            <scale>1 1 1</scale>
            <uri>model://armmy_omnibot/meshes/omni_wheel/wheel_assembly.dae</uri>
          </mesh>
        </geometry>
      </visual>
      <self_collide>false</self_collide>
    </link>
    <joint name='roller_third_1_joint' type='revolute'>
      <pose relative_to='third_wheel_link'>0.015 0.0046 0 0 0 1</pose>
      <parent>third_wheel_link</parent>
      <child>roller_third_1_link</child>
      <axis>
        <xyz>0 0 1</xyz>
        <limit>
          <lower>-10000000000000000</lower>
          <upper>10000000000000000</upper>
        </limit>
        <dynamics>
          <spring_reference>0</spring_reference>
          <spring_stiffness>0</spring_stiffness>
        </dynamics>
      </axis>
    </joint>
    <link name='roller_third_1_link'>
      <pose relative_to='roller_third_1_joint'>0 0 0 0 0 0</pose>
      <inertial>
        <pose>0 0.00925 0 1.570796327 0 0</pose>
        <mass>0.001</mass>
        <inertia>
          <ixx>1.6e-07</ixx>
          <ixy>0</ixy>
          <ixz>0</ixz>
          <iyy>1.6e-07</iyy>
          <iyz>0</iyz>
          <izz>1.6e-07</izz>
        </inertia>
      </inertial>
      <collision name='roller_third_1_link_collision'>
        <pose>0.015 0.0046 0 0 0 1</pose>
        <geometry>
          <sphere>
            <radius>0.02</radius>
          </sphere>
        </geometry>
      </collision>
      <visual name='roller_third_1_link_visual'>
        <pose>0.015 0.0046 0 0 0 1</pose>
        <geometry>
          <sphere>
            <radius>0.02</radius>
          </sphere>
        </geometry>
        <material>
          <diffuse>0 0 0 1</diffuse>
          <ambient>0 0 0 1</ambient>
        </material>
      </visual>
    </link>
    <joint name='roller_third_2_joint' type='revolute'>
      <pose relative_to='third_wheel_link'>0 0.0046 0.015 -1 0 0</pose>
      <parent>third_wheel_link</parent>
      <child>roller_third_2_link</child>
      <axis>
        <xyz>-1 0 0</xyz>
        <limit>
          <lower>-10000000000000000</lower>
          <upper>10000000000000000</upper>
        </limit>
        <dynamics>
          <spring_reference>0</spring_reference>
          <spring_stiffness>0</spring_stiffness>
        </dynamics>
      </axis>
    </joint>
    <link name='roller_third_2_link'>
      <pose relative_to='roller_third_2_joint'>0 0 0 0 0 0</pose>
      <inertial>
        <pose>0 0.00925 0 1.570796327 0 0</pose>
        <mass>0.001</mass>
        <inertia>
          <ixx>1.6e-07</ixx>
          <ixy>0</ixy>
          <ixz>0</ixz>
          <iyy>1.6e-07</iyy>
          <iyz>0</iyz>
          <izz>1.6e-07</izz>
        </inertia>
      </inertial>
      <collision name='roller_third_2_link_collision'>
        <pose>0 0.0046 0.015 -1 0 0</pose>
        <geometry>
          <sphere>
            <radius>0.02</radius>
          </sphere>
        </geometry>
      </collision>
      <visual name='roller_third_2_link_visual'>
        <pose>0 0.0046 0.015 -1 0 0</pose>
        <geometry>
          <sphere>
            <radius>0.02</radius>
          </sphere>
        </geometry>
        <material>
          <diffuse>0 0 0 1</diffuse>
          <ambient>0 0 0 1</ambient>
        </material>
      </visual>
    </link>
    <joint name='roller_third_3_joint' type='revolute'>
      <pose relative_to='third_wheel_link'>-0.015 0.0046 0 0 0 -1</pose>
      <parent>third_wheel_link</parent>
      <child>roller_third_3_link</child>
      <axis>
        <xyz>0 0 -1</xyz>
        <limit>
          <lower>-10000000000000000</lower>
          <upper>10000000000000000</upper>
        </limit>
        <dynamics>
          <spring_reference>0</spring_reference>
          <spring_stiffness>0</spring_stiffness>
        </dynamics>
      </axis>
    </joint>
    <link name='roller_third_3_link'>
      <pose relative_to='roller_third_3_joint'>0 0 0 0 0 0</pose>
      <inertial>
        <pose>0 0.00925 0 1.570796327 0 0</pose>
        <mass>0.001</mass>
        <inertia>
          <ixx>1.6e-07</ixx>
          <ixy>0</ixy>
          <ixz>0</ixz>
          <iyy>1.6e-07</iyy>
          <iyz>0</iyz>
          <izz>1.6e-07</izz>
        </inertia>
      </inertial>
      <collision name='roller_third_3_link_collision'>
        <pose>-0.015 0.0046 0 0 0 -1</pose>
        <geometry>
          <sphere>
            <radius>0.02</radius>
          </sphere>
        </geometry>
      </collision>
      <visual name='roller_third_3_link_visual'>
        <pose>-0.015 0.0046 0 0 0 -1</pose>
        <geometry>
          <sphere>
            <radius>0.02</radius>
          </sphere>
        </geometry>
        <material>
          <diffuse>0 0 0 1</diffuse>
          <ambient>0 0 0 1</ambient>
        </material>
      </visual>
    </link>
    <joint name='roller_third_4_joint' type='revolute'>
      <pose relative_to='third_wheel_link'>0 0.0046 -0.015 1 0 0</pose>
      <parent>third_wheel_link</parent>
      <child>roller_third_4_link</child>
      <axis>
        <xyz>1 0 0</xyz>
        <limit>
          <lower>-10000000000000000</lower>
          <upper>10000000000000000</upper>
        </limit>
        <dynamics>
          <spring_reference>0</spring_reference>
          <spring_stiffness>0</spring_stiffness>
        </dynamics>
      </axis>
    </joint>
    <link name='roller_third_4_link'>
      <pose relative_to='roller_third_4_joint'>0 0 0 0 0 0</pose>
      <inertial>
        <pose>0 0.00925 0 1.570796327 0 0</pose>
        <mass>0.001</mass>
        <inertia>
          <ixx>1.6e-07</ixx>
          <ixy>0</ixy>
          <ixz>0</ixz>
          <iyy>1.6e-07</iyy>
          <iyz>0</iyz>
          <izz>1.6e-07</izz>
        </inertia>
      </inertial>
      <collision name='roller_third_4_link_collision'>
        <pose>0 0.0046 -0.015 1 0 0</pose>
        <geometry>
          <sphere>
            <radius>0.02</radius>
          </sphere>
        </geometry>
      </collision>
      <visual name='roller_third_4_link_visual'>
        <pose>0 0.0046 -0.015 1 0 0</pose>
        <geometry>
          <sphere>
            <radius>0.02</radius>
          </sphere>
        </geometry>
        <material>
          <diffuse>0 0 0 1</diffuse>
          <ambient>0 0 0 1</ambient>
        </material>
      </visual>
    </link>
    <joint name='roller_third_5_joint' type='revolute'>
      <pose relative_to='third_wheel_link'>0.0106 0.0139 0.0106 -0.707107 0 0.707107</pose>
      <parent>third_wheel_link</parent>
      <child>roller_third_5_link</child>
      <axis>
        <xyz>-0.707107 0 0.707107</xyz>
        <limit>
          <lower>-10000000000000000</lower>
          <upper>10000000000000000</upper>
        </limit>
        <dynamics>
          <spring_reference>0</spring_reference>
          <spring_stiffness>0</spring_stiffness>
        </dynamics>
      </axis>
    </joint>
    <link name='roller_third_5_link'>
      <pose relative_to='roller_third_5_joint'>0 0 0 0 0 0</pose>
      <inertial>
        <pose>0 0.00925 0 1.570796327 0 0</pose>
        <mass>0.001</mass>
        <inertia>
          <ixx>1.6e-07</ixx>
          <ixy>0</ixy>
          <ixz>0</ixz>
          <iyy>1.6e-07</iyy>
          <iyz>0</iyz>
          <izz>1.6e-07</izz>
        </inertia>
      </inertial>
      <collision name='roller_third_5_link_collision'>
        <pose>0.0106 0.0139 0.0106 -0.707107 0 0.707107</pose>
        <geometry>
          <sphere>
            <radius>0.02</radius>
          </sphere>
        </geometry>
      </collision>
      <visual name='roller_third_5_link_visual'>
        <pose>0.0106 0.0139 0.0106 -0.707107 0 0.707107</pose>
        <geometry>
          <sphere>
            <radius>0.02</radius>
          </sphere>
        </geometry>
        <material>
          <diffuse>0 0 0 1</diffuse>
          <ambient>0 0 0 1</ambient>
        </material>
      </visual>
    </link>
    <joint name='roller_third_6_joint' type='revolute'>
      <pose relative_to='third_wheel_link'>-0.0106 0.0139 0.0106 -0.707107 0 -0.707107</pose>
      <parent>third_wheel_link</parent>
      <child>roller_third_6_link</child>
      <axis>
        <xyz>-0.707107 0 -0.707107</xyz>
        <limit>
          <lower>-10000000000000000</lower>
          <upper>10000000000000000</upper>
        </limit>
        <dynamics>
          <spring_reference>0</spring_reference>
          <spring_stiffness>0</spring_stiffness>
        </dynamics>
      </axis>
    </joint>
    <link name='roller_third_6_link'>
      <pose relative_to='roller_third_6_joint'>0 0 0 0 0 0</pose>
      <inertial>
        <pose>0 0.00925 0 1.570796327 0 0</pose>
        <mass>0.001</mass>
        <inertia>
          <ixx>1.6e-07</ixx>
          <ixy>0</ixy>
          <ixz>0</ixz>
          <iyy>1.6e-07</iyy>
          <iyz>0</iyz>
          <izz>1.6e-07</izz>
        </inertia>
      </inertial>
      <collision name='roller_third_6_link_collision'>
        <pose>-0.0106 0.0139 0.0106 -0.707107 0 -0.707107</pose>
        <geometry>
          <sphere>
            <radius>0.02</radius>
          </sphere>
        </geometry>
      </collision>
      <visual name='roller_third_6_link_visual'>
        <pose>-0.0106 0.0139 0.0106 -0.707107 0 -0.707107</pose>
        <geometry>
          <sphere>
            <radius>0.02</radius>
          </sphere>
        </geometry>
        <material>
          <diffuse>0 0 0 1</diffuse>
          <ambient>0 0 0 1</ambient>
        </material>
      </visual>
    </link>
    <joint name='roller_third_7_joint' type='revolute'>
      <pose relative_to='third_wheel_link'>-0.0106 0.0139 -0.0106 0.707107 0 -0.707107</pose>
      <parent>third_wheel_link</parent>
      <child>roller_third_7_link</child>
      <axis>
        <xyz>0.707107 0 -0.707107</xyz>
        <limit>
          <lower>-10000000000000000</lower>
          <upper>10000000000000000</upper>
        </limit>
        <dynamics>
          <spring_reference>0</spring_reference>
          <spring_stiffness>0</spring_stiffness>
        </dynamics>
      </axis>
    </joint>
    <link name='roller_third_7_link'>
      <pose relative_to='roller_third_7_joint'>0 0 0 0 0 0</pose>
      <inertial>
        <pose>0 0.00925 0 1.570796327 0 0</pose>
        <mass>0.001</mass>
        <inertia>
          <ixx>1.6e-07</ixx>
          <ixy>0</ixy>
          <ixz>0</ixz>
          <iyy>1.6e-07</iyy>
          <iyz>0</iyz>
          <izz>1.6e-07</izz>
        </inertia>
      </inertial>
      <collision name='roller_third_7_link_collision'>
        <pose>-0.0106 0.0139 -0.0106 0.707107 0 -0.707107</pose>
        <geometry>
          <sphere>
            <radius>0.02</radius>
          </sphere>
        </geometry>
      </collision>
      <visual name='roller_third_7_link_visual'>
        <pose>-0.0106 0.0139 -0.0106 0.707107 0 -0.707107</pose>
        <geometry>
          <sphere>
            <radius>0.02</radius>
          </sphere>
        </geometry>
        <material>
          <diffuse>0 0 0 1</diffuse>
          <ambient>0 0 0 1</ambient>
        </material>
      </visual>
    </link>
    <joint name='roller_third_8_joint' type='revolute'>
      <pose relative_to='third_wheel_link'>0.0106 0.0139 -0.0106 0.707107 0 0.707107</pose>
      <parent>third_wheel_link</parent>
      <child>roller_third_8_link</child>
      <axis>
        <xyz>0.707107 0 0.707107</xyz>
        <limit>
          <lower>-10000000000000000</lower>
          <upper>10000000000000000</upper>
        </limit>
        <dynamics>
          <spring_reference>0</spring_reference>
          <spring_stiffness>0</spring_stiffness>
        </dynamics>
      </axis>
    </joint>
    <link name='roller_third_8_link'>
      <pose relative_to='roller_third_8_joint'>0 0 0 0 0 0</pose>
      <inertial>
        <pose>0 0.00925 0 1.570796327 0 0</pose>
        <mass>0.001</mass>
        <inertia>
          <ixx>1.6e-07</ixx>
          <ixy>0</ixy>
          <ixz>0</ixz>
          <iyy>1.6e-07</iyy>
          <iyz>0</iyz>
          <izz>1.6e-07</izz>
        </inertia>
      </inertial>
      <collision name='roller_third_8_link_collision'>
        <pose>0.0106 0.0139 -0.0106 0.707107 0 0.707107</pose>
        <geometry>
          <sphere>
            <radius>0.02</radius>
          </sphere>
        </geometry>
      </collision>
      <visual name='roller_third_8_link_visual'>
        <pose>0.0106 0.0139 -0.0106 0.707107 0 0.707107</pose>
        <geometry>
          <sphere>
            <radius>0.02</radius>
          </sphere>
        </geometry>
        <material>
          <diffuse>0 0 0 1</diffuse>
          <ambient>0 0 0 1</ambient>
        </material>
      </visual>
    </link>
    <plugin name='gz_ros2_control::GazeboSimROS2ControlPlugin' filename='libgz_ros2_control-system.so'>
      <parameters>/home/armmy2530/Documents/ros2/ros2EIC/install/armmy_omnibot/share/armmy_omnibot/config/ros2_controller/my_controllers.yaml</parameters>
    </plugin>
    <frame name='top_imu_joint' attached_to='base_link'>
      <pose>0 0 0.05 0 -0 0</pose>
    </frame>
    <frame name='top_imu_link' attached_to='top_imu_joint'/>
    <frame name='top_lidar_joint' attached_to='base_link'>
      <pose>0 0 0.05 0 -0 0</pose>
    </frame>
    <frame name='top_lidar_link' attached_to='top_lidar_joint'/>
    <frame name='base_link_joint' attached_to='base_footprint'>
      <pose>0 0 0 0 -0 0.785398</pose>
    </frame>
    <frame name='base_link' attached_to='base_link_joint'/>
  </model>
</sdf>
