<?xml version="1.0"?>
<robot xmlns:xacro="http://www.ros.org/wiki/xacro">

    <xacro:include filename="inertial_macros.xacro" />

    <xacro:property name="chassis_length" value="0.140" />
    <xacro:property name="chassis_width" value="0.140" />
    <xacro:property name="chassis_height" value="0.143" />
    <xacro:property name="chassis_mass" value="1.0" />
    <xacro:property name="wheel_radius" value="0.033" />
    <xacro:property name="wheel_thickness" value="0.026" />
    <xacro:property name="wheel_mass" value="0.05" />
    <xacro:property name="wheel_offset_x" value="0.226" />
    <xacro:property name="wheel_offset_y" value="0.08" />
    <xacro:property name="wheel_offset_z" value="0.01" />
    <xacro:property name="caster_wheel_radius" value="0.0056" />
    <xacro:property name="caster_wheel_mass" value="0.01" />
    <xacro:property name="caster_wheel_offset_x" value="-0.081" />
    <xacro:property name="caster_wheel_offset_z" value="-0.004" />

    <!-- Init colour -->
    <material name="black">
        <color rgba="0.0 0.0 0.0 1.0" />
    </material>

    <material name="dark">
        <color rgba="0.3 0.3 0.3 1.0" />
    </material>

    <material name="light_black">
        <color rgba="0.4 0.4 0.4 1.0" />
    </material>

    <material name="blue">
        <color rgba="0.0 0.0 0.8 1.0" />
    </material>

    <material name="green">
        <color rgba="0.0 0.8 0.0 1.0" />
    </material>

    <material name="grey">
        <color rgba="0.5 0.5 0.5 1.0" />
    </material>

    <material name="orange">
        <color rgba="1.0 0.4235 0.0392 1.0" />
    </material>

    <material name="brown">
        <color rgba="0.8706 0.8118 0.7647 1.0" />
    </material>

    <material name="red">
        <color rgba="0.8 0.0 0.0 1.0" />
    </material>

    <material name="white">
        <color rgba="1.0 1.0 1.0 1.0" />
    </material>

    <link name="base_footprint" />

    <joint name="base_joint" type="fixed">
        <parent link="base_footprint" />
        <child link="base_link" />
        <origin xyz="0.0 0.0 0.010" rpy="0 0 0" />
    </joint>

    <link name="base_link">
        <visual>
            <origin xyz="-0.032 0 0.0" rpy="0 0 0" />
            <geometry>
                <mesh
                    filename="package://turtlebot3_common/meshes/burger_base.dae"
                    scale="0.001 0.001 0.001" />
            </geometry>
            <material name="light_black" />
        </visual>

        <collision>
            <origin xyz="-0.032 0 0.070" rpy="0 0 0" />
            <geometry>
                <box size="0.140 0.140 0.143" />
            </geometry>
        </collision>

        <xacro:inertial_box mass="0.5" x="${chassis_length}" y="${chassis_width}"
            z="${chassis_height}">
            <origin xyz="-0.05 0 0" rpy="0 0 0" />
        </xacro:inertial_box>
    </link>

    <joint name="wheel_left_joint" type="continuous">
        <parent link="base_link" />
        <child link="wheel_left_link" />
        <origin xyz="0.0 0.08 0.023" rpy="-1.57 0 0" />
        <axis xyz="0 0 1" />
    </joint>

    <link name="wheel_left_link">
        <visual>
            <origin xyz="0 0 0" rpy="1.57 0 0" />
            <geometry>
                <mesh
                    filename="package://turtlebot3_common/meshes/tire.dae"
                    scale="0.001 0.001 0.001" />
            </geometry>
            <material name="dark" />
        </visual>

        <collision name="wheel_left_collision">
            <origin xyz="0 0 0" rpy="0 0 0" />
            <geometry>
                <sphere radius="0.033" />
            </geometry>
        </collision>

        <xacro:inertial_cylinder mass="${wheel_mass}" length="${wheel_thickness}"
            radius="${wheel_radius}">
            <origin xyz="0 0 0" rpy="0 0 0" />
        </xacro:inertial_cylinder>
    </link>

    <joint name="wheel_right_joint" type="continuous">
        <parent link="base_link" />
        <child link="wheel_right_link" />
        <origin xyz="0.0 -0.080 0.023" rpy="-1.57 0 0" />
        <axis xyz="0 0 1" />
    </joint>

    <link name="wheel_right_link">
        <visual>
            <origin xyz="0 0 0" rpy="1.57 0 0" />
            <geometry>
                <mesh
                    filename="package://turtlebot3_common/meshes/tire.dae"
                    scale="0.001 0.001 0.001" />
            </geometry>
            <material name="dark" />
        </visual>

        <collision name="wheel_right_collision">
            <origin xyz="0 0 0" rpy="0 0 0" />
            <geometry>
                <sphere radius="0.033" />
            </geometry>
        </collision>

        <xacro:inertial_cylinder mass="${wheel_mass}" length="${wheel_thickness}"
            radius="${wheel_radius}">
            <origin xyz="0 0 0" rpy="0 0 0" />
        </xacro:inertial_cylinder>
    </link>


    <gazebo reference="caster_back_link">
        <material>Gazebo/White</material>
        <mu1 value="0.001" />
        <mu2 value="0.001" />
    </gazebo>

    <!-- CASTER WHEEL LINK -->

    <joint name="caster_wheel_joint" type="fixed">
        <parent link="base_link" />
        <child link="caster_wheel" />
        <origin xyz="${caster_wheel_offset_x} 0 ${caster_wheel_offset_z}" />
    </joint>

    <link name="caster_wheel">
        <visual>
            <geometry>
                <sphere radius="${caster_wheel_radius}" />
            </geometry>
            <material name="white" />
        </visual>
        <collision>
            <geometry>
                <sphere radius="${caster_wheel_radius}" />
            </geometry>
        </collision>
        <xacro:inertial_sphere mass="${caster_wheel_mass}" radius="${caster_wheel_radius}">
            <origin xyz="0 0 0" rpy="0 0 0" />
        </xacro:inertial_sphere>
    </link>

    <gazebo reference="caster_wheel">
        <material>Gazebo/White</material>
        <mu1 value="0.001" />
        <mu2 value="0.001" />
    </gazebo>
</robot>